<?xml version="1.0" ?>
<!-- =================================================================================== -->
<!-- |    This document was autogenerated by xacro from Kwad.xacro                     | -->
<!-- |    EDITING THIS FILE BY HAND IS NOT RECOMMENDED                                 | -->
<!-- =================================================================================== -->
<robot name="Kwad">
  <material name="white">
    <color rgba="0.8 0.8 0.8 1"/>
  </material>
  <material name="black">
    <color rgba="0.1 0.1 0.1 1"/>
  </material>
  <material name="red">
    <color rgba="0.8 0.01 0.01 1"/>
  </material>
  <material name="blue">
    <color rgba="0.01 0.01 0.8 1"/>
  </material>
  <material name="golden">
    <color rgba="0.8313725490196079 0.6862745098039216 0.21568627450980393 1"/>
  </material>
  <!-- ================= MATERIALS ================= -->
  <gazebo reference="base_link1">
    <material>Gazebo/Red</material>
  </gazebo>
  <gazebo reference="base_link2">
    <material>Gazebo/Red</material>
  </gazebo>
  <gazebo reference="base_link3">
    <material>Gazebo/White</material>
  </gazebo>
  <gazebo reference="plate1">
    <material>Gazebo/Black</material>
  </gazebo>
  <gazebo reference="plate2">
    <material>Gazebo/Blue</material>
  </gazebo>
  <gazebo reference="cyl1">
    <material>Gazebo/Gold</material>
  </gazebo>
  <gazebo reference="cyl2">
    <material>Gazebo/Gold</material>
  </gazebo>
  <gazebo reference="cyl3">
    <material>Gazebo/Gold</material>
  </gazebo>
  <gazebo reference="cyl4">
    <material>Gazebo/Gold</material>
  </gazebo>
  <gazebo reference="cyl5">
    <material>Gazebo/Gold</material>
  </gazebo>
  <gazebo reference="cyl6">
    <material>Gazebo/Gold</material>
  </gazebo>
  <gazebo reference="prop_front_right">
    <material>Gazebo/Black</material>
  </gazebo>
  <gazebo reference="prop_front_left">
    <material>Gazebo/Black</material>
  </gazebo>
  <gazebo reference="prop_back_right">
    <material>Gazebo/Black</material>
  </gazebo>
  <gazebo reference="prop_back_left">
    <material>Gazebo/Black</material>
  </gazebo>
  <gazebo reference="prop_right">
    <material>Gazebo/Black</material>
  </gazebo>
  <gazebo reference="prop_left">
    <material>Gazebo/Black</material>
  </gazebo>
  <!-- ================= CAMERA ================= -->
  <gazebo reference="camera_link">
    <sensor name="camera1" type="camera">
      <update_rate>30</update_rate>
      <camera name="head">
        <horizontal_fov>1.3962634</horizontal_fov>
        <image>
          <width>800</width>
          <height>800</height>
          <format>R8G8B8</format>
        </image>
        <clip>
          <near>0.02</near>
          <far>300</far>
        </clip>
        <noise>
          <type>gaussian</type>
          <mean>0</mean>
          <stddev>0.007</stddev>
        </noise>
      </camera>
      <plugin filename="libgazebo_ros_camera.so" name="camera_controller">
        <ros>
          <namespace>/Kwad</namespace>
        </ros>
        <alwaysOn>true</alwaysOn>
        <updateRate>0.0</updateRate>
        <cameraName>Kwad/camera1</cameraName>
        <imageTopicName>image_raw</imageTopicName>
        <cameraInfoTopicName>camera_info</cameraInfoTopicName>
        <frameName>camera_link</frameName>
        <hackBaseline>0.07</hackBaseline>
        <distortionK1>0.0</distortionK1>
        <distortionK2>0.0</distortionK2>
        <distortionK3>0.0</distortionK3>
        <distortionT1>0.0</distortionT1>
        <distortionT2>0.0</distortionT2>
      </plugin>
    </sensor>
  </gazebo>
  <!-- ================= LIFT-DRAG PROPELLERS ================= -->
  <!-- CW props (upward -1), CCW props (upward 1) -->
  <gazebo>
    <plugin filename="libLiftDragPlugin.so" name="quad_prop1">
      <a0>0.1</a0>
      <cla>0.1</cla>
      <cda>0.01</cda>
      <cma>0.0</cma>
      <alpha_stall>0.2</alpha_stall>
      <cla_stall>-0.2</cla_stall>
      <cda_stall>1.0</cda_stall>
      <cma_stall>0.0</cma_stall>
      <cp>0 0.5 0</cp>
      <area>0.762</area>
      <air_density>1.2041</air_density>
      <forward>1 0 0</forward>
      <upward>0 0 -1</upward>
      <link_name>prop_front_right</link_name>
      <control_joint>joint_front_right_prop</control_joint>
    </plugin>
  </gazebo>
  <gazebo>
    <plugin filename="libLiftDragPlugin.so" name="quad_prop2">
      <a0>0.1</a0>
      <cla>0.1</cla>
      <cda>0.01</cda>
      <cma>0.0</cma>
      <alpha_stall>0.2</alpha_stall>
      <cla_stall>-0.2</cla_stall>
      <cda_stall>1.0</cda_stall>
      <cma_stall>0.0</cma_stall>
      <cp>0 0.5 0</cp>
      <area>0.762</area>
      <air_density>1.2041</air_density>
      <forward>1 0 0</forward>
      <upward>0 0 1</upward>
      <link_name>prop_front_left</link_name>
      <control_joint>joint_front_left_prop</control_joint>
    </plugin>
  </gazebo>
  <gazebo>
    <plugin filename="libLiftDragPlugin.so" name="quad_prop3">
      <a0>0.1</a0>
      <cla>0.1</cla>
      <cda>0.01</cda>
      <cma>0.0</cma>
      <alpha_stall>0.2</alpha_stall>
      <cla_stall>-0.2</cla_stall>
      <cda_stall>1.0</cda_stall>
      <cma_stall>0.0</cma_stall>
      <cp>0 0.5 0</cp>
      <area>0.762</area>
      <air_density>1.2041</air_density>
      <forward>1 0 0</forward>
      <upward>0 0 -1</upward>
      <link_name>prop_back_right</link_name>
      <control_joint>joint_back_right_prop</control_joint>
    </plugin>
  </gazebo>
  <gazebo>
    <plugin filename="libLiftDragPlugin.so" name="quad_prop4">
      <a0>0.1</a0>
      <cla>0.1</cla>
      <cda>0.01</cda>
      <cma>0.0</cma>
      <alpha_stall>0.2</alpha_stall>
      <cla_stall>-0.2</cla_stall>
      <cda_stall>1.0</cda_stall>
      <cma_stall>0.0</cma_stall>
      <cp>0 0.5 0</cp>
      <area>0.762</area>
      <air_density>1.2041</air_density>
      <forward>1 0 0</forward>
      <upward>0 0 1</upward>
      <link_name>prop_back_left</link_name>
      <control_joint>joint_back_left_prop</control_joint>
    </plugin>
  </gazebo>
  <gazebo>
    <plugin filename="libLiftDragPlugin.so" name="quad_prop5">
      <a0>0.1</a0>
      <cla>0.1</cla>
      <cda>0.01</cda>
      <cma>0.0</cma>
      <alpha_stall>0.2</alpha_stall>
      <cla_stall>-0.2</cla_stall>
      <cda_stall>1.0</cda_stall>
      <cma_stall>0.0</cma_stall>
      <cp>0 0.5 0</cp>
      <area>0.762</area>
      <air_density>1.2041</air_density>
      <forward>1 0 0</forward>
      <upward>0 0 -1</upward>
      <link_name>prop_left</link_name>
      <control_joint>joint_left_prop</control_joint>
    </plugin>
  </gazebo>
  <gazebo>
    <plugin filename="libLiftDragPlugin.so" name="quad_prop6">
      <a0>0.1</a0>
      <cla>0.1</cla>
      <cda>0.01</cda>
      <cma>0.0</cma>
      <alpha_stall>0.2</alpha_stall>
      <cla_stall>-0.2</cla_stall>
      <cda_stall>1.0</cda_stall>
      <cma_stall>0.0</cma_stall>
      <cp>0 0.5 0</cp>
      <area>0.762</area>
      <air_density>1.2041</air_density>
      <forward>1 0 0</forward>
      <upward>0 0 1</upward>
      <link_name>prop_right</link_name>
      <control_joint>joint_right_prop</control_joint>
    </plugin>
  </gazebo>
  <!-- ================= ROS CONTROL PLUGIN ================= -->
  <gazebo>
    <plugin filename="libgazebo_ros_control.so" name="gazebo_ros_control">
      <ros>
        <namespace>/Kwad</namespace>
      </ros>
      <robotSimType>gazebo_ros_control/DefaultRobotHWSim</robotSimType>
    </plugin>
  </gazebo>
  <!-- ======================================================== -->
  <link name="base_link1">
    <visual>
      <origin rpy="0 0 0.5235987716666667" xyz="0 0 0"/>
      <geometry>
        <box size="0.0315 0.45 0.01"/>
      </geometry>
      <material name="red"/>
    </visual>
    <collision>
      <origin rpy="0 0 0.5235987716666667" xyz="0 0 0"/>
      <geometry>
        <box size="0.0315 0.45 0.01"/>
      </geometry>
    </collision>
    <inertial>
      <origin rpy="0 0 0.5235987716666667" xyz="0 0 0"/>
      <mass value="0.5"/>
      <inertia ixx="0.024945" ixy="0" ixz="0" iyy="0.024945" iyz="0" izz="0.120285"/>
    </inertial>
  </link>
  <!-- ======================================================== -->
  <link name="base_link2">
    <visual>
      <origin rpy="0 0 -0.5235987716666667" xyz="0 0 0"/>
      <geometry>
        <box size="0.0315 0.45 0.01"/>
      </geometry>
      <material name="red"/>
    </visual>
    <collision>
      <origin rpy="0 0 -0.5235987716666667" xyz="0     0 0"/>
      <geometry>
        <box size="0.0315 0.45 0.01"/>
      </geometry>
    </collision>
    <inertial>
      <origin rpy="0 0 -0.5235987716666667" xyz="0 0 0"/>
      <mass value="0.5"/>
      <inertia ixx="0.024945" ixy="0" ixz="0" iyy="0.024945" iyz="0" izz="0.120285"/>
    </inertial>
  </link>
  <!-- ======================================================== -->
  <link name="base_link3">
    <visual>
      <origin rpy="0 0 1.570796315" xyz="0 0 0"/>
      <geometry>
        <box size="0.0315 0.45 0.01"/>
      </geometry>
      <material name="white"/>
    </visual>
    <collision>
      <origin rpy="0 0 1.570796315" xyz="0     0 0"/>
      <geometry>
        <box size="0.0315 0.45 0.01"/>
      </geometry>
    </collision>
    <inertial>
      <origin rpy="0 0 1.570796315" xyz="0 0 0"/>
      <mass value="0.5"/>
      <inertia ixx="0.024945" ixy="0" ixz="0" iyy="0.024945" iyz="0" izz="0.120285"/>
    </inertial>
  </link>
  <link name="plate1">
    <visual>
      <origin rpy="0 0 0" xyz="0 0 0"/>
      <geometry>
        <box size="0.12 0.12 0.01"/>
      </geometry>
      <material name="black"/>
    </visual>
    <collision>
      <origin rpy="0 0 0" xyz="0 0 0"/>
      <geometry>
        <box size="0.12 0.12 0.01"/>
      </geometry>
    </collision>
    <inertial>
      <origin rpy="0 0 0" xyz="0 0 0"/>
      <mass value="0.01"/>
      <inertia ixx="0" ixy="0" ixz="0" iyy="0" iyz="0" izz="-2.6"/>
    </inertial>
  </link>
  <!-- ======================================================== -->
  <link name="plate2">
    <visual>
      <origin rpy="0 0 0" xyz="0 0 0"/>
      <geometry>
        <box size="0.05 0.03 0.005"/>
      </geometry>
      <material name="blue"/>
    </visual>
    <collision>
      <origin rpy="0 0 0" xyz="0 0 0"/>
      <geometry>
        <box size="0.05 0.03 0.005"/>
      </geometry>
    </collision>
    <inertial>
      <origin rpy="0 0 0" xyz="0 0 0"/>
      <mass value="0.001"/>
      <inertia ixx="0" ixy="0" ixz="0" iyy="0" iyz="0" izz="1.1666000000000007"/>
    </inertial>
  </link>
  <!-- ======================================================== -->
  <link name="cyl1">
    <visual>
      <origin rpy="0 0 1.570796315" xyz="0 0 0"/>
      <geometry>
        <cylinder length="0.02" radius="0.016"/>
      </geometry>
      <material name="golden"/>
    </visual>
    <collision>
      <origin rpy="0 0 1.570796315" xyz="0 0 0"/>
      <geometry>
        <cylinder length="0.02" radius="0.016"/>
      </geometry>
    </collision>
    <inertial>
      <origin rpy="0 0 0" xyz="0 0 0"/>
      <mass value="0.01"/>
      <inertia ixx="8.95e-06" ixy="0" ixz="0" iyy="8.95e-06" iyz="0" izz="0.000223"/>
    </inertial>
  </link>
  <!-- ======================================================== -->
  <link name="cyl2">
    <visual>
      <origin rpy="0 0 0" xyz="0 0 0"/>
      <geometry>
        <cylinder length="0.02" radius="0.016"/>
      </geometry>
      <material name="golden"/>
    </visual>
    <collision>
      <origin rpy="0 0 0" xyz="0 0 0"/>
      <geometry>
        <cylinder length="0.02" radius="0.016"/>
      </geometry>
    </collision>
    <inertial>
      <origin rpy="0 0 0" xyz="0 0 0"/>
      <mass value="0.01"/>
      <inertia ixx="8.95e-06" ixy="0" ixz="0" iyy="8.95e-06" iyz="0" izz="0.000223"/>
    </inertial>
  </link>
  <!-- ======================================================== -->
  <link name="cyl3">
    <visual>
      <origin rpy="0 0 0" xyz="0 0 0"/>
      <geometry>
        <cylinder length="0.02" radius="0.016"/>
      </geometry>
      <material name="golden"/>
    </visual>
    <collision>
      <origin rpy="0 0 0" xyz="0 0 0"/>
      <geometry>
        <cylinder length="0.02" radius="0.016"/>
      </geometry>
    </collision>
    <inertial>
      <origin rpy="0 0 0" xyz="0 0 0"/>
      <mass value="0.01"/>
      <inertia ixx="8.95e-06" ixy="0" ixz="0" iyy="8.95e-06" iyz="0" izz="0.000223"/>
    </inertial>
  </link>
  <!-- ======================================================== -->
  <link name="cyl4">
    <visual>
      <origin rpy="0 0 0" xyz="0 0 0"/>
      <geometry>
        <cylinder length="0.02" radius="0.016"/>
      </geometry>
      <material name="golden"/>
    </visual>
    <collision>
      <origin rpy="0 0 0" xyz="0 0 0"/>
      <geometry>
        <cylinder length="0.02" radius="0.016"/>
      </geometry>
    </collision>
    <inertial>
      <origin rpy="0 0 0" xyz="0 0 0"/>
      <mass value="0.01"/>
      <inertia ixx="8.95e-06" ixy="0" ixz="0" iyy="8.95e-06" iyz="0" izz="0.000223"/>
    </inertial>
  </link>
  <link name="cyl5">
    <visual>
      <origin rpy="0 0 0" xyz="0 0 0"/>
      <geometry>
        <cylinder length="0.02" radius="0.016"/>
      </geometry>
      <material name="golden"/>
    </visual>
    <collision>
      <origin rpy="0 0 0" xyz="0 0 0"/>
      <geometry>
        <cylinder length="0.02" radius="0.016"/>
      </geometry>
    </collision>
    <inertial>
      <origin rpy="0 0 0" xyz="0 0 0"/>
      <mass value="0.01"/>
      <inertia ixx="8.95e-06" ixy="0" ixz="0" iyy="8.95e-06" iyz="0" izz="0.000223"/>
    </inertial>
  </link>
  <link name="cyl6">
    <visual>
      <origin rpy="0 0 0" xyz="0 0 0"/>
      <geometry>
        <cylinder length="0.02" radius="0.016"/>
      </geometry>
      <material name="golden"/>
    </visual>
    <collision>
      <origin rpy="0 0 0" xyz="0 0 0"/>
      <geometry>
        <cylinder length="0.02" radius="0.016"/>
      </geometry>
    </collision>
    <inertial>
      <origin rpy="0 0 0" xyz="0 0 0"/>
      <mass value="0.01"/>
      <inertia ixx="8.95e-06" ixy="0" ixz="0" iyy="8.95e-06" iyz="0" izz="0.000223"/>
    </inertial>
  </link>
  <!-- ======================================================== -->
  <link name="arduino">
    <visual>
      <origin rpy="0 0 0" xyz="0 0 0"/>
      <geometry>
        <mesh filename="package://fly_bot/meshes/22V10.dae" scale="0.005 0.005 0.005"/>
      </geometry>
    </visual>
    <collision>
      <origin rpy="0 0 0" xyz="0 0 0"/>
      <geometry>
        <box size="0.1 0.1 0.001"/>
      </geometry>
    </collision>
    <inertial>
      <origin rpy="0 0 0" xyz="0 0 0"/>
      <mass value="0.05"/>
      <inertia ixx="0" ixy="0" ixz="0" iyy="0" iyz="0" izz="8.33333e-05"/>
    </inertial>
  </link>
  <!-- ======================================================== -->
  <link name="camera_link">
    <visual>
      <origin rpy="0 0 0" xyz="0 0 0"/>
      <geometry>
        <box size="0.01 0.01 0.01"/>
      </geometry>
      <material name="red"/>
    </visual>
    <collision>
      <origin rpy="0 0 0" xyz="0 0 0"/>
      <geometry>
        <box size="0.01 0.01 0.01"/>
      </geometry>
    </collision>
    <inertial>
      <origin rpy="0 0 0" xyz="0 0 0"/>
      <mass value="1e-05"/>
      <inertia ixx="1e-06" ixy="0" ixz="0" iyy="1e-06" iyz="0" izz="1e-06"/>
    </inertial>
  </link>
  <!-- ======================================================== -->
  <!-- Propellers of the quad: fr, fl, br, bl -->
  <link name="prop_front_right">
    <visual>
      <origin rpy="0 0 0" xyz="0 0 0"/>
      <geometry>
        <box size="0.011006666666666666 0.16000000000000003 0.001"/>
      </geometry>
      <material name="black"/>
    </visual>
    <collision>
      <origin rpy="0 0 0" xyz="0 0 0"/>
      <geometry>
        <box size="0.011006666666666666 0.16000000000000003 0.001"/>
      </geometry>
    </collision>
    <inertial>
      <origin rpy="0 0 0" xyz="0 0 0"/>
      <mass value="0.0055"/>
      <inertia ixx="0" ixy="0" ixz="0" iyy="0" iyz="0" izz="4.42448e-05"/>
    </inertial>
  </link>
  <link name="prop_front_left">
    <visual>
      <origin rpy="0 0 0" xyz="0 0 0"/>
      <geometry>
        <box size="0.011006666666666666 0.16000000000000003 0.001"/>
      </geometry>
      <material name="black"/>
    </visual>
    <collision>
      <origin rpy="0 0 0" xyz="0 0 0"/>
      <geometry>
        <box size="0.011006666666666666 0.16000000000000003 0.001"/>
      </geometry>
    </collision>
    <inertial>
      <origin rpy="0 0 0" xyz="0 0 0"/>
      <mass value="0.0055"/>
      <inertia ixx="0" ixy="0" ixz="0" iyy="0" iyz="0" izz="4.42448e-05"/>
    </inertial>
  </link>
  <link name="prop_back_right">
    <visual>
      <origin rpy="0 0 0" xyz="0 0 0"/>
      <geometry>
        <box size="0.011006666666666666 0.16000000000000003 0.001"/>
      </geometry>
      <material name="black"/>
    </visual>
    <collision>
      <origin rpy="0 0 0" xyz="0 0 0"/>
      <geometry>
        <box size="0.011006666666666666 0.16000000000000003 0.001"/>
      </geometry>
    </collision>
    <inertial>
      <origin rpy="0 0 0" xyz="0 0 0"/>
      <mass value="0.0055"/>
      <inertia ixx="0" ixy="0" ixz="0" iyy="0" iyz="0" izz="4.42448e-05"/>
    </inertial>
  </link>
  <link name="prop_back_left">
    <visual>
      <origin rpy="0 0 0" xyz="0 0 0"/>
      <geometry>
        <box size="0.011006666666666666 0.16000000000000003 0.001"/>
      </geometry>
      <material name="black"/>
    </visual>
    <collision>
      <origin rpy="0 0 0" xyz="0 0 0"/>
      <geometry>
        <box size="0.011006666666666666 0.16000000000000003 0.001"/>
      </geometry>
    </collision>
    <inertial>
      <origin rpy="0 0 0" xyz="0 0 0"/>
      <mass value="0.0055"/>
      <inertia ixx="0" ixy="0" ixz="0" iyy="0" iyz="0" izz="4.42448e-05"/>
    </inertial>
  </link>
  <link name="prop_left">
    <visual>
      <origin rpy="0 0 0" xyz="0 0 0"/>
      <geometry>
        <box size="0.011006666666666666 0.16000000000000003 0.001"/>
      </geometry>
      <material name="black"/>
    </visual>
    <collision>
      <origin rpy="0 0 0" xyz="0 0 0"/>
      <geometry>
        <box size="0.011006666666666666 0.16000000000000003 0.001"/>
      </geometry>
    </collision>
    <inertial>
      <origin rpy="0 0 0" xyz="0 0 0"/>
      <mass value="0.0055"/>
      <inertia ixx="0" ixy="0" ixz="0" iyy="0" iyz="0" izz="4.42448e-05"/>
    </inertial>
  </link>
  <link name="prop_right">
    <visual>
      <origin rpy="0 0 0" xyz="0 0 0"/>
      <geometry>
        <box size="0.011006666666666666 0.16000000000000003 0.001"/>
      </geometry>
      <material name="black"/>
    </visual>
    <collision>
      <origin rpy="0 0 0" xyz="0 0 0"/>
      <geometry>
        <box size="0.011006666666666666 0.16000000000000003 0.001"/>
      </geometry>
    </collision>
    <inertial>
      <origin rpy="0 0 0" xyz="0 0 0"/>
      <mass value="0.0055"/>
      <inertia ixx="0" ixy="0" ixz="0" iyy="0" iyz="0" izz="4.42448e-05"/>
    </inertial>
  </link>
  <!-- ======================================================== -->
  <!-- Define the joint between the arms of the frame -->
  <joint name="center" type="fixed">
    <parent link="base_link1"/>
    <child link="base_link2"/>
    <origin rpy="0 0 0" xyz="0 0 0"/>
    <axis xyz="0 0 1"/>
  </joint>
  <joint name="center2" type="fixed">
    <parent link="base_link2"/>
    <child link="base_link3"/>
    <origin rpy="0 0 0" xyz="0 0 0"/>
    <axis xyz="0 0 1"/>
  </joint>
  <!-- ======================================================== -->
  <!-- Define joint between prop fr and frame -->
  <joint name="joint_front_right_prop" type="continuous">
    <parent link="base_link2"/>
    <child link="prop_front_right"/>
    <origin rpy="0 0 0" xyz="0.1 0.1732 0.021"/>
    <axis xyz="0 0 1"/>
  </joint>
  <!-- ======================================================== -->
  <!-- Define joint between prop fl and frame -->
  <joint name="joint_front_left_prop" type="continuous">
    <parent link="base_link1"/>
    <child link="prop_front_left"/>
    <origin rpy="0 0 0" xyz="-0.1 0.1732 0.021"/>
    <axis xyz="0 0 1"/>
  </joint>
  <!-- ======================================================== -->
  <!-- Define joint between prop br and frame -->
  <joint name="joint_back_right_prop" type="continuous">
    <parent link="base_link1"/>
    <child link="prop_back_right"/>
    <origin rpy="0 0 0" xyz="-0.1 -0.1732 0.021"/>
    <axis xyz="0 0 1"/>
  </joint>
  <!-- ======================================================== -->
  <!-- Define joint between prop br and frame -->
  <joint name="joint_back_left_prop" type="continuous">
    <parent link="base_link2"/>
    <child link="prop_back_left"/>
    <origin rpy="0 0 0" xyz="0.1 -0.1732 0.021"/>
    <axis xyz="0 0 1"/>
  </joint>
  <joint name="joint_left_prop" type="continuous">
    <parent link="base_link3"/>
    <child link="prop_left"/>
    <origin rpy="0 0 0" xyz="-0.200 0 0.021"/>
    <axis xyz="0 0 1"/>
  </joint>
  <joint name="joint_right_prop" type="continuous">
    <parent link="base_link3"/>
    <child link="prop_right"/>
    <origin rpy="0 0 0" xyz="0.200 0 0.021"/>
    <axis xyz="0 0 1"/>
  </joint>
  <!-- ======================================================== -->
  <!-- Define joint between plate1 and frame -->
  <joint name="joint_plate1_frame" type="fixed">
    <parent link="base_link2"/>
    <child link="plate1"/>
    <origin rpy="0 0 0" xyz="0 0 0.005"/>
    <axis xyz="0 0 1"/>
  </joint>
  <!-- ======================================================== -->
  <!-- Define joint between plate1 and plate2 -->
  <joint name="joint_plate2_frame" type="fixed">
    <parent link="plate1"/>
    <child link="plate2"/>
    <origin rpy="0 0 0" xyz="0 0 0.007"/>
    <axis xyz="0 0 1"/>
  </joint>
  <!-- ======================================================== -->
  <!-- Define joint between cyl1 and frame -->
  <joint name="joint_cyl1_frame" type="fixed">
    <parent link="base_link2"/>
    <child link="cyl1"/>
    <origin rpy="0 0 0" xyz="0.1 0.1732 0.01"/>
    <axis xyz="0 0 1"/>
  </joint>
  <!-- ======================================================== -->
  <!-- Define joint between cyl2 and frame -->
  <joint name="joint_cyl2_frame" type="fixed">
    <parent link="base_link2"/>
    <child link="cyl2"/>
    <origin rpy="0 0 0" xyz="-0.1 0.1732 0.01"/>
    <axis xyz="0 0 1"/>
  </joint>
  <!-- ======================================================== -->
  <!-- Define joint between cyl3 and frame -->
  <joint name="joint_cyl3_frame" type="fixed">
    <parent link="base_link1"/>
    <child link="cyl3"/>
    <origin rpy="0 0 0" xyz="-0.1 -0.1732 0.01"/>
    <axis xyz="0 0 1"/>
  </joint>
  <!-- ======================================================== -->
  <!-- Define joint between cyl4 and frame -->
  <joint name="joint_cyl4_frame" type="fixed">
    <parent link="base_link1"/>
    <child link="cyl4"/>
    <origin rpy="0 0 0" xyz="0.1 -0.1732 0.01"/>
    <axis xyz="0 0 1"/>
  </joint>
  <joint name="joint_cyl5_frame" type="fixed">
    <parent link="base_link1"/>
    <child link="cyl5"/>
    <origin rpy="0 0 0" xyz="0.200 0 0.01"/>
    <axis xyz="0 0 1"/>
  </joint>
  <joint name="joint_cyl6_frame" type="fixed">
    <parent link="base_link1"/>
    <child link="cyl6"/>
    <origin rpy="0 0 0" xyz="-0.200 0 0.01"/>
    <axis xyz="0 0 1"/>
  </joint>
  <!-- ======================================================== -->
  <!-- Define joint between Arduino and frame -->
  <joint name="joint_arduino_frame" type="fixed">
    <parent link="plate2"/>
    <child link="arduino"/>
    <origin rpy="0 0 0" xyz="0 0 0.005"/>
    <axis xyz="0 0 1"/>
  </joint>
  <!-- ======================================================== -->
  <!-- Define joint between Arduino and frame -->
  <joint name="joint_camera_frame" type="fixed">
    <parent link="plate2"/>
    <child link="camera_link"/>
    <origin rpy="0 0.1 0" xyz="0.03 0 0.005"/>
    <axis xyz="0 0 1"/>
  </joint>
  <!-- ======================================================== -->
  <!-- Add transmission elements -->
  <transmission name="front_right_motor_joint">
    <type>transmission_interface/SimpleTransmission</type>
    <joint name="joint_front_right_prop">
      <hardwareInterface>hardware_interface/VelocityJointInterface</hardwareInterface>
    </joint>
    <actuator name="BLDC_motor1">
      <hardwareInterface>hardware_interface/VelocityJointInterface</hardwareInterface>
      <mechanicalReduction>1</mechanicalReduction>
    </actuator>
  </transmission>
  <transmission name="front_left_motor_joint">
    <type>transmission_interface/SimpleTransmission</type>
    <joint name="joint_front_left_prop">
      <hardwareInterface>hardware_interface/VelocityJointInterface</hardwareInterface>
    </joint>
    <actuator name="BLDC_motor2">
      <hardwareInterface>hardware_interface/VelocityJointInterface</hardwareInterface>
      <mechanicalReduction>1</mechanicalReduction>
    </actuator>
  </transmission>
  <transmission name="left_motor_joint">
    <type>transmission_interface/SimpleTransmission</type>
    <joint name="joint_left_prop">
      <hardwareInterface>hardware_interface/VelocityJointInterface</hardwareInterface>
    </joint>
    <actuator name="BLDC_motor6">
      <hardwareInterface>hardware_interface/VelocityJointInterface</hardwareInterface>
      <mechanicalReduction>1</mechanicalReduction>
    </actuator>
  </transmission>
  <transmission name="back_right_motor_joint">
    <type>transmission_interface/SimpleTransmission</type>
    <joint name="joint_back_right_prop">
      <hardwareInterface>hardware_interface/VelocityJointInterface</hardwareInterface>
    </joint>
    <actuator name="BLDC_motor3">
      <hardwareInterface>hardware_interface/VelocityJointInterface</hardwareInterface>
      <mechanicalReduction>1</mechanicalReduction>
    </actuator>
  </transmission>
  <transmission name="back_left_motor_joint">
    <type>transmission_interface/SimpleTransmission</type>
    <joint name="joint_back_left_prop">
      <hardwareInterface>hardware_interface/VelocityJointInterface</hardwareInterface>
    </joint>
    <actuator name="BLDC_motor4">
      <hardwareInterface>hardware_interface/VelocityJointInterface</hardwareInterface>
      <mechanicalReduction>1</mechanicalReduction>
    </actuator>
  </transmission>
  <transmission name="right_motor_joint">
    <type>transmission_interface/SimpleTransmission</type>
    <joint name="joint_right_prop">
      <hardwareInterface>hardware_interface/VelocityJointInterface</hardwareInterface>
    </joint>
    <actuator name="BLDC_motor5">
      <hardwareInterface>hardware_interface/VelocityJointInterface</hardwareInterface>
      <mechanicalReduction>1</mechanicalReduction>
    </actuator>
  </transmission>
</robot>

